2021-07-10 13:19:43,062 ERROR: Exception on /login [GET] [in c:\users\hp\appdata\local\programs\python\python39\lib\site-packages\flask\app.py:1891]
Traceback (most recent call last):
  File "c:\users\hp\appdata\local\programs\python\python39\lib\site-packages\flask\app.py", line 2447, in wsgi_app
    response = self.full_dispatch_request()
  File "c:\users\hp\appdata\local\programs\python\python39\lib\site-packages\flask\app.py", line 1952, in full_dispatch_request
    rv = self.handle_user_exception(e)
  File "c:\users\hp\appdata\local\programs\python\python39\lib\site-packages\flask\app.py", line 1821, in handle_user_exception
    reraise(exc_type, exc_value, tb)
  File "c:\users\hp\appdata\local\programs\python\python39\lib\site-packages\flask\_compat.py", line 39, in reraise
    raise value
  File "c:\users\hp\appdata\local\programs\python\python39\lib\site-packages\flask\app.py", line 1950, in full_dispatch_request
    rv = self.dispatch_request()
  File "c:\users\hp\appdata\local\programs\python\python39\lib\site-packages\flask\app.py", line 1936, in dispatch_request
    return self.view_functions[rule.endpoint](**req.view_args)
  File "C:\Users\HP\Microblogging - Site\Flask_Web_Application\microblog\app\routes.py", line 72, in login
    return render_template('login.html', form = form, title = 'Sign In')
  File "c:\users\hp\appdata\local\programs\python\python39\lib\site-packages\flask\templating.py", line 137, in render_template
    return _render(
  File "c:\users\hp\appdata\local\programs\python\python39\lib\site-packages\flask\templating.py", line 120, in _render
    rv = template.render(context)
  File "c:\users\hp\appdata\local\programs\python\python39\lib\site-packages\jinja2\environment.py", line 1090, in render
    self.environment.handle_exception()
  File "c:\users\hp\appdata\local\programs\python\python39\lib\site-packages\jinja2\environment.py", line 832, in handle_exception
    reraise(*rewrite_traceback_stack(source=source))
  File "c:\users\hp\appdata\local\programs\python\python39\lib\site-packages\jinja2\_compat.py", line 28, in reraise
    raise value.with_traceback(tb)
  File "C:\Users\HP\Microblogging - Site\Flask_Web_Application\microblog\app\templates\login.html", line 1, in top-level template code
    {% extends "base.html" %}
  File "C:\Users\HP\Microblogging - Site\Flask_Web_Application\microblog\app\templates\base.html", line 31, in top-level template code
    {% block content %}{% endblock %}
  File "C:\Users\HP\Microblogging - Site\Flask_Web_Application\microblog\app\templates\login.html", line 24, in block "content"
    <p>New User? <a href="{{ url_for('register') }}">Click to Register!</a></p>
  File "c:\users\hp\appdata\local\programs\python\python39\lib\site-packages\flask\helpers.py", line 370, in url_for
    return appctx.app.handle_url_build_error(error, endpoint, values)
  File "c:\users\hp\appdata\local\programs\python\python39\lib\site-packages\flask\app.py", line 2216, in handle_url_build_error
    reraise(exc_type, exc_value, tb)
  File "c:\users\hp\appdata\local\programs\python\python39\lib\site-packages\flask\_compat.py", line 39, in reraise
    raise value
  File "c:\users\hp\appdata\local\programs\python\python39\lib\site-packages\flask\helpers.py", line 357, in url_for
    rv = url_adapter.build(
  File "c:\users\hp\appdata\local\programs\python\python39\lib\site-packages\werkzeug\routing.py", line 2179, in build
    raise BuildError(endpoint, values, method, self)
werkzeug.routing.BuildError: Could not build url for endpoint 'reset_password_request'. Did you mean 'edit_profile' instead?
2021-07-24 10:49:00,681 INFO: Microblog startup [in C:\Users\HP\Microblogging - Site\Flask_Web_Application\microblog\app\__init__.py:74]
2021-07-24 10:49:22,246 ERROR: Exception on / [GET] [in c:\users\hp\appdata\local\programs\python\python39\lib\site-packages\flask\app.py:1891]
Traceback (most recent call last):
  File "c:\users\hp\appdata\local\programs\python\python39\lib\site-packages\sqlalchemy\engine\base.py", line 1770, in _execute_context
    self.dialect.do_execute(
  File "c:\users\hp\appdata\local\programs\python\python39\lib\site-packages\sqlalchemy\engine\default.py", line 717, in do_execute
    cursor.execute(statement, parameters)
sqlite3.OperationalError: no such table: user

The above exception was the direct cause of the following exception:

Traceback (most recent call last):
  File "c:\users\hp\appdata\local\programs\python\python39\lib\site-packages\flask\app.py", line 2447, in wsgi_app
    response = self.full_dispatch_request()
  File "c:\users\hp\appdata\local\programs\python\python39\lib\site-packages\flask\app.py", line 1952, in full_dispatch_request
    rv = self.handle_user_exception(e)
  File "c:\users\hp\appdata\local\programs\python\python39\lib\site-packages\flask\app.py", line 1821, in handle_user_exception
    reraise(exc_type, exc_value, tb)
  File "c:\users\hp\appdata\local\programs\python\python39\lib\site-packages\flask\_compat.py", line 39, in reraise
    raise value
  File "c:\users\hp\appdata\local\programs\python\python39\lib\site-packages\flask\app.py", line 1948, in full_dispatch_request
    rv = self.preprocess_request()
  File "c:\users\hp\appdata\local\programs\python\python39\lib\site-packages\flask\app.py", line 2242, in preprocess_request
    rv = func()
  File "C:\Users\HP\Microblogging - Site\Flask_Web_Application\microblog\app\main\routes.py", line 16, in before_request
    if current_user.is_authenticated:
  File "c:\users\hp\appdata\local\programs\python\python39\lib\site-packages\werkzeug\local.py", line 347, in __getattr__
    return getattr(self._get_current_object(), name)
  File "c:\users\hp\appdata\local\programs\python\python39\lib\site-packages\werkzeug\local.py", line 306, in _get_current_object
    return self.__local()
  File "c:\users\hp\appdata\local\programs\python\python39\lib\site-packages\flask_login\utils.py", line 26, in <lambda>
    current_user = LocalProxy(lambda: _get_user())
  File "c:\users\hp\appdata\local\programs\python\python39\lib\site-packages\flask_login\utils.py", line 346, in _get_user
    current_app.login_manager._load_user()
  File "c:\users\hp\appdata\local\programs\python\python39\lib\site-packages\flask_login\login_manager.py", line 318, in _load_user
    user = self._user_callback(user_id)
  File "C:\Users\HP\Microblogging - Site\Flask_Web_Application\microblog\app\models.py", line 82, in load_user
    return User.query.get(int(id))
  File "<string>", line 2, in get
  File "c:\users\hp\appdata\local\programs\python\python39\lib\site-packages\sqlalchemy\util\deprecations.py", line 390, in warned
    return fn(*args, **kwargs)
  File "c:\users\hp\appdata\local\programs\python\python39\lib\site-packages\sqlalchemy\orm\query.py", line 942, in get
    return self._get_impl(ident, loading.load_on_pk_identity)
  File "c:\users\hp\appdata\local\programs\python\python39\lib\site-packages\sqlalchemy\orm\query.py", line 946, in _get_impl
    return self.session._get_impl(
  File "c:\users\hp\appdata\local\programs\python\python39\lib\site-packages\sqlalchemy\orm\session.py", line 2839, in _get_impl
    return db_load_fn(
  File "c:\users\hp\appdata\local\programs\python\python39\lib\site-packages\sqlalchemy\orm\loading.py", line 531, in load_on_pk_identity
    session.execute(
  File "c:\users\hp\appdata\local\programs\python\python39\lib\site-packages\sqlalchemy\orm\session.py", line 1689, in execute
    result = conn._execute_20(statement, params or {}, execution_options)
  File "c:\users\hp\appdata\local\programs\python\python39\lib\site-packages\sqlalchemy\engine\base.py", line 1582, in _execute_20
    return meth(self, args_10style, kwargs_10style, execution_options)
  File "c:\users\hp\appdata\local\programs\python\python39\lib\site-packages\sqlalchemy\sql\elements.py", line 323, in _execute_on_connection
    return connection._execute_clauseelement(
  File "c:\users\hp\appdata\local\programs\python\python39\lib\site-packages\sqlalchemy\engine\base.py", line 1451, in _execute_clauseelement
    ret = self._execute_context(
  File "c:\users\hp\appdata\local\programs\python\python39\lib\site-packages\sqlalchemy\engine\base.py", line 1813, in _execute_context
    self._handle_dbapi_exception(
  File "c:\users\hp\appdata\local\programs\python\python39\lib\site-packages\sqlalchemy\engine\base.py", line 1994, in _handle_dbapi_exception
    util.raise_(
  File "c:\users\hp\appdata\local\programs\python\python39\lib\site-packages\sqlalchemy\util\compat.py", line 207, in raise_
    raise exception
  File "c:\users\hp\appdata\local\programs\python\python39\lib\site-packages\sqlalchemy\engine\base.py", line 1770, in _execute_context
    self.dialect.do_execute(
  File "c:\users\hp\appdata\local\programs\python\python39\lib\site-packages\sqlalchemy\engine\default.py", line 717, in do_execute
    cursor.execute(statement, parameters)
sqlalchemy.exc.OperationalError: (sqlite3.OperationalError) no such table: user
[SQL: SELECT user.id AS user_id, user.username AS user_username, user.email AS user_email, user.password_hash AS user_password_hash, user.about_me AS user_about_me, user.last_seen AS user_last_seen 
FROM user 
WHERE user.id = ?]
[parameters: (1,)]
(Background on this error at: http://sqlalche.me/e/14/e3q8)
2021-07-24 10:56:02,789 INFO: Microblog startup [in C:\Users\HP\Microblogging - Site\Flask_Web_Application\microblog\app\__init__.py:74]
2021-07-24 10:56:09,513 INFO: Microblog startup [in C:\Users\HP\Microblogging - Site\Flask_Web_Application\microblog\app\__init__.py:74]
2021-07-24 10:56:17,330 INFO: Microblog startup [in C:\Users\HP\Microblogging - Site\Flask_Web_Application\microblog\app\__init__.py:74]
